Workbook
Name FiltroDati_Coppia___Cross: #N/A

Sheet Dati
A1: Coppia / Cross | B1: Data | C1: Orario | D1: Mese | E1: Giorno settimana | F1: Direzione | G1: RISCHIO % | H1: RR FINALE 1: | I1: Pips tp | J1: Pips stop loss | K1: Risultato | L1: Risultato % | M1: Risultato valuta | N1: Tf d'entrata | O1: SCREEN PRE | P1: SCREEN POST | Q1: note | R1: PRO | S1: CONTRO | T1: EquityCurve | U1: Emozioni | V1: Tf allineati | W1: Setup | X1: % Sentiment | Y1: Cot report
A2: XAUUSD | B2: 45975 | C2: 0.60416667 | D2: =IF($B2="", "", CHOOSE(MONTH($B2), "Gennaio","Febbraio","Marzo","Aprile","Maggio","Giugno","Luglio","Agosto","Settembre","Ottobre","Novembre","Dicembre")) -> Novembre | E2: =IF($B2="", "", CHOOSE(WEEKDAY($B2,2), "Lunedì","Martedì","Mercoledì","Giovedì","Venerdì","Sabato","Domenica")) -> Venerdì | F2: Long | G2: 0.005 | H2: 3.5 | I2: 35 | J2: 10 | K2: Target | L2: =IF($K2="Target", $G2*$H2, IF($K2="Stop Loss", -$G2, IF($K2="Breakeven", 0, ""))) -> 0.0175 | M2: 175 | N2: m5 | O2: https://www.tradingview.com/x/B0kTAu4P/ https://www.tradingview.com/x/B0kTAu4P/ | Q2: m1 barrier | T2: =IF($L2="", "", $L2) -> 0.0175 | W2: asiatica
D3: =IF($B3="", "", CHOOSE(MONTH($B3), "Gennaio","Febbraio","Marzo","Aprile","Maggio","Giugno","Luglio","Agosto","Settembre","Ottobre","Novembre","Dicembre")) | E3: =IF($B3="", "", CHOOSE(WEEKDAY($B3,2), "Lunedì","Martedì","Mercoledì","Giovedì","Venerdì","Sabato","Domenica")) | L3: =IF($K3="Target", $G3*$H3, IF($K3="Stop Loss", -$G3, IF($K3="Breakeven", 0, ""))) | T3: =IF($L3="", "", $T2 + $L3)
D4: =IF($B4="", "", CHOOSE(MONTH($B4), "Gennaio","Febbraio","Marzo","Aprile","Maggio","Giugno","Luglio","Agosto","Settembre","Ottobre","Novembre","Dicembre")) | E4: =IF($B4="", "", CHOOSE(WEEKDAY($B4,2), "Lunedì","Martedì","Mercoledì","Giovedì","Venerdì","Sabato","Domenica")) | L4: =IF($K4="Target", $G4*$H4, IF($K4="Stop Loss", -$G4, IF($K4="Breakeven", 0, ""))) | T4: =IF($L4="", "", $T3 + $L4)
D5: =IF($B5="", "", CHOOSE(MONTH($B5), "Gennaio","Febbraio","Marzo","Aprile","Maggio","Giugno","Luglio","Agosto","Settembre","Ottobre","Novembre","Dicembre")) | E5: =IF($B5="", "", CHOOSE(WEEKDAY($B5,2), "Lunedì","Martedì","Mercoledì","Giovedì","Venerdì","Sabato","Domenica")) | L5: =IF($K5="Target", $G5*$H5, IF($K5="Stop Loss", -$G5, IF($K5="Breakeven", 0, ""))) | T5: =IF($L5="", "", $T4 + $L5)
D6: =IF($B6="", "", CHOOSE(MONTH($B6), "Gennaio","Febbraio","Marzo","Aprile","Maggio","Giugno","Luglio","Agosto","Settembre","Ottobre","Novembre","Dicembre")) | E6: =IF($B6="", "", CHOOSE(WEEKDAY($B6,2), "Lunedì","Martedì","Mercoledì","Giovedì","Venerdì","Sabato","Domenica")) | L6: =IF($K6="Target", $G6*$H6, IF($K6="Stop Loss", -$G6, IF($K6="Breakeven", 0, ""))) | T6: =IF($L6="", "", $T5 + $L6)
D7: =IF($B7="", "", CHOOSE(MONTH($B7), "Gennaio","Febbraio","Marzo","Aprile","Maggio","Giugno","Luglio","Agosto","Settembre","Ottobre","Novembre","Dicembre")) | E7: =IF($B7="", "", CHOOSE(WEEKDAY($B7,2), "Lunedì","Martedì","Mercoledì","Giovedì","Venerdì","Sabato","Domenica")) | L7: =IF($K7="Target", $G7*$H7, IF($K7="Stop Loss", -$G7, IF($K7="Breakeven", 0, ""))) | T7: =IF($L7="", "", $T6 + $L7)
D8: =IF($B8="", "", CHOOSE(MONTH($B8), "Gennaio","Febbraio","Marzo","Aprile","Maggio","Giugno","Luglio","Agosto","Settembre","Ottobre","Novembre","Dicembre")) | E8: =IF($B8="", "", CHOOSE(WEEKDAY($B8,2), "Lunedì","Martedì","Mercoledì","Giovedì","Venerdì","Sabato","Domenica")) | L8: =IF($K8="Target", $G8*$H8, IF($K8="Stop Loss", -$G8, IF($K8="Breakeven", 0, ""))) | T8: =IF($L8="", "", $T7 + $L8) | AA8: colonne con colore diverso da non modificare, si autocompilano
D9: =IF($B9="", "", CHOOSE(MONTH($B9), "Gennaio","Febbraio","Marzo","Aprile","Maggio","Giugno","Luglio","Agosto","Settembre","Ottobre","Novembre","Dicembre")) | E9: =IF($B9="", "", CHOOSE(WEEKDAY($B9,2), "Lunedì","Martedì","Mercoledì","Giovedì","Venerdì","Sabato","Domenica")) | L9: =IF($K9="Target", $G9*$H9, IF($K9="Stop Loss", -$G9, IF($K9="Breakeven", 0, ""))) | T9: =IF($L9="", "", $T8 + $L9)
D10: =IF($B10="", "", CHOOSE(MONTH($B10), "Gennaio","Febbraio","Marzo","Aprile","Maggio","Giugno","Luglio","Agosto","Settembre","Ottobre","Novembre","Dicembre")) | E10: =IF($B10="", "", CHOOSE(WEEKDAY($B10,2), "Lunedì","Martedì","Mercoledì","Giovedì","Venerdì","Sabato","Domenica")) | L10: =IF($K10="Target", $G10*$H10, IF($K10="Stop Loss", -$G10, IF($K10="Breakeven", 0, ""))) | T10: =IF($L10="", "", $T9 + $L10)
D11: =IF($B11="", "", CHOOSE(MONTH($B11), "Gennaio","Febbraio","Marzo","Aprile","Maggio","Giugno","Luglio","Agosto","Settembre","Ottobre","Novembre","Dicembre")) | E11: =IF($B11="", "", CHOOSE(WEEKDAY($B11,2), "Lunedì","Martedì","Mercoledì","Giovedì","Venerdì","Sabato","Domenica")) | L11: =IF($K11="Target", $G11*$H11, IF($K11="Stop Loss", -$G11, IF($K11="Breakeven", 0, ""))) | T11: =IF($L11="", "", $T10 + $L11)
D12: =IF($B12="", "", CHOOSE(MONTH($B12), "Gennaio","Febbraio","Marzo","Aprile","Maggio","Giugno","Luglio","Agosto","Settembre","Ottobre","Novembre","Dicembre")) | E12: =IF($B12="", "", CHOOSE(WEEKDAY($B12,2), "Lunedì","Martedì","Mercoledì","Giovedì","Venerdì","Sabato","Domenica")) | L12: =IF($K12="Target", $G12*$H12, IF($K12="Stop Loss", -$G12, IF($K12="Breakeven", 0, ""))) | T12: =IF($L12="", "", $T11 + $L12)
D13: =IF($B13="", "", CHOOSE(MONTH($B13), "Gennaio","Febbraio","Marzo","Aprile","Maggio","Giugno","Luglio","Agosto","Settembre","Ottobre","Novembre","Dicembre")) | E13: =IF($B13="", "", CHOOSE(WEEKDAY($B13,2), "Lunedì","Martedì","Mercoledì","Giovedì","Venerdì","Sabato","Domenica")) | L13: =IF($K13="Target", $G13*$H13, IF($K13="Stop Loss", -$G13, IF($K13="Breakeven", 0, ""))) | T13: =IF($L13="", "", $T12 + $L13)
D14: =IF($B14="", "", CHOOSE(MONTH($B14), "Gennaio","Febbraio","Marzo","Aprile","Maggio","Giugno","Luglio","Agosto","Settembre","Ottobre","Novembre","Dicembre")) | E14: =IF($B14="", "", CHOOSE(WEEKDAY($B14,2), "Lunedì","Martedì","Mercoledì","Giovedì","Venerdì","Sabato","Domenica")) | L14: =IF($K14="Target", $G14*$H14, IF($K14="Stop Loss", -$G14, IF($K14="Breakeven", 0, ""))) | T14: =IF($L14="", "", $T13 + $L14)
D15: =IF($B15="", "", CHOOSE(MONTH($B15), "Gennaio","Febbraio","Marzo","Aprile","Maggio","Giugno","Luglio","Agosto","Settembre","Ottobre","Novembre","Dicembre")) | E15: =IF($B15="", "", CHOOSE(WEEKDAY($B15,2), "Lunedì","Martedì","Mercoledì","Giovedì","Venerdì","Sabato","Domenica")) | L15: =IF($K15="Target", $G15*$H15, IF($K15="Stop Loss", -$G15, IF($K15="Breakeven", 0, ""))) | T15: =IF($L15="", "", $T14 + $L15)
D16: =IF($B16="", "", CHOOSE(MONTH($B16), "Gennaio","Febbraio","Marzo","Aprile","Maggio","Giugno","Luglio","Agosto","Settembre","Ottobre","Novembre","Dicembre")) | E16: =IF($B16="", "", CHOOSE(WEEKDAY($B16,2), "Lunedì","Martedì","Mercoledì","Giovedì","Venerdì","Sabato","Domenica")) | L16: =IF($K16="Target", $G16*$H16, IF($K16="Stop Loss", -$G16, IF($K16="Breakeven", 0, ""))) | T16: =IF($L16="", "", $T15 + $L16)
D17: =IF($B17="", "", CHOOSE(MONTH($B17), "Gennaio","Febbraio","Marzo","Aprile","Maggio","Giugno","Luglio","Agosto","Settembre","Ottobre","Novembre","Dicembre")) | E17: =IF($B17="", "", CHOOSE(WEEKDAY($B17,2), "Lunedì","Martedì","Mercoledì","Giovedì","Venerdì","Sabato","Domenica")) | L17: =IF($K17="Target", $G17*$H17, IF($K17="Stop Loss", -$G17, IF($K17="Breakeven", 0, ""))) | T17: =IF($L17="", "", $T16 + $L17)
D18: =IF($B18="", "", CHOOSE(MONTH($B18), "Gennaio","Febbraio","Marzo","Aprile","Maggio","Giugno","Luglio","Agosto","Settembre","Ottobre","Novembre","Dicembre")) | E18: =IF($B18="", "", CHOOSE(WEEKDAY($B18,2), "Lunedì","Martedì","Mercoledì","Giovedì","Venerdì","Sabato","Domenica")) | L18: =IF($K18="Target", $G18*$H18, IF($K18="Stop Loss", -$G18, IF($K18="Breakeven", 0, ""))) | T18: =IF($L18="", "", $T17 + $L18)
D19: =IF($B19="", "", CHOOSE(MONTH($B19), "Gennaio","Febbraio","Marzo","Aprile","Maggio","Giugno","Luglio","Agosto","Settembre","Ottobre","Novembre","Dicembre")) | E19: =IF($B19="", "", CHOOSE(WEEKDAY($B19,2), "Lunedì","Martedì","Mercoledì","Giovedì","Venerdì","Sabato","Domenica")) | L19: =IF($K19="Target", $G19*$H19, IF($K19="Stop Loss", -$G19, IF($K19="Breakeven", 0, ""))) | T19: =IF($L19="", "", $T18 + $L19)
D20: =IF($B20="", "", CHOOSE(MONTH($B20), "Gennaio","Febbraio","Marzo","Aprile","Maggio","Giugno","Luglio","Agosto","Settembre","Ottobre","Novembre","Dicembre")) | E20: =IF($B20="", "", CHOOSE(WEEKDAY($B20,2), "Lunedì","Martedì","Mercoledì","Giovedì","Venerdì","Sabato","Domenica")) | L20: =IF($K20="Target", $G20*$H20, IF($K20="Stop Loss", -$G20, IF($K20="Breakeven", 0, ""))) | T20: =IF($L20="", "", $T19 + $L20)
... D2001: =IF($B2001="", "", CHOOSE(MONTH($B2001), "Gennaio","Febbraio","Marzo","Aprile","Maggio","Giugno","Luglio","Agosto","Settembre","Ottobre","Novembre","Dicembre")) | E2001: =IF($B2001="", "", CHOOSE(WEEKDAY($B2001,2), "Lunedì","Martedì","Mercoledì","Giovedì","Venerdì","Sabato","Domenica")) | L2001: =IF($K2001="Target", $G2001*$H2001, IF($K2001="Stop Loss", -$G2001, IF($K2001="Breakeven", 0, ""))) | T2001: =IF($L2001="", "", $T2000 + $L2001)

Sheet Statistiche
A1: Target | B1: =COUNTIF(Dati!$K$2:$K$2000,"Target") -> 1 | C1: Conteggio di Risultato | D1: Etichette di colonna | H1: Win rate%
A2: Stop Loss | B2: =COUNTIF(Dati!$K$2:$K$2000,"Stop Loss") -> 0 | C2: Etichette di riga | D2: Breakeven | E2: Stop Loss | F2: Target | G2: Totale | H2: =IF(SUM(D3:F3)=0, "", F3/SUM(D3:F3)) -> 1
A3: Breakeven | B3: =COUNTIF(Dati!$K$2:$K$2000,"Breakeven") -> 0 | C3: AUDUSD | D3: 0 | E3: 0 | F3: 3 | G3: 3 | H3: =IF(SUM(D4:F4)=0, "", F4/SUM(D4:F4)) -> 0
A4: Win | B4: =B1+B3 -> 1 | C4: EURJPY | D4: 0 | E4: 1 | F4: 0 | G4: 1 | H4: =IF(SUM(D5:F5)=0, "", F5/SUM(D5:F5)) -> 0
A5: Tot operazioni | B5: =SUM(B1:B3) -> 1 | C5: EURUSD | D5: 0 | E5: 1 | F5: 0 | G5: 1 | H5: =IF(SUM(D6:F6)=0, "", F6/SUM(D6:F6)) -> 0.66666667 | AS5: barrier con target o stop loss
A6: Media % Realizzata | B6: =IFERROR(AVERAGE(Dati!$L$2:$L$2000),"") -> 0.0175 | C6: GBPJPY | D6: 1 | E6: 0 | F6: 2 | G6: 3 | H6: =IF(SUM(D7:F7)=0, "", F7/SUM(D7:F7)) -> 1
A7: Long Totali | B7: =COUNTIF(Dati!$F$2:$F$2000,"Long") -> 1 | C7: GBPUSD | D7: 0 | E7: 0 | F7: 1 | G7: 1 | H7: =IF(SUM(D8:F8)=0, "", F8/SUM(D8:F8)) -> 1
A8: Short Totali | B8: =COUNTIF(Dati!$F$2:$F$2000,"Short") -> 0 | C8: USDCAD | D8: 0 | E8: 0 | F8: 1 | G8: 1 | H8: =IF(SUM(D9:F9)=0, "", F9/SUM(D9:F9)) -> 1
A9: Win Rate | B9: =IFERROR(B1/B5, 0) -> 1 | C9: USDJPY | D9: 0 | E9: 0 | F9: 1 | G9: 1 | H9: =IF(SUM(D10:F10)=0, "", F10/SUM(D10:F10)) -> 1
A10: Media Target | B10: =IFERROR(AVERAGEIF(Dati!$K$2:$K$2000, "Target", Dati!$L$2:$L$2000), "") -> 0.0175 | C10: XAUUSD | D10: 0 | E10: 0 | F10: 2 | G10: 2 | H10: =IF(SUM(D11:F11)=0, "", F11/SUM(D11:F11)) -> 0
A11: Media Stop Loss | B11: =IFERROR(AVERAGEIF(Dati!$K$2:$K$2000, "Stop Loss", Dati!$L$2:$L$2000), "") | C11: XAGUSD | D11: 0 | E11: 1 | F11: 0 | G11: 1 | H11: =IF(SUM(D12:F12)=0, "", F12/SUM(D12:F12)) -> 0
A12: RR MEDIO | B12: =IFERROR(AVERAGEIF(Dati!$K$2:$K$2000, "Target", Dati!$H$2:$H$2000), "") -> 3.5 | C12: CADJPY | D12: 0 | E12: 1 | F12: 0 | G12: 1
A13: Equity Totale | B13: =IFERROR(LOOKUP(9.99E+307, Dati!$T$2:$T$2000), 0) -> 0.0175
A14: Profit Factor | B14: =IFERROR(SUMIFS(Dati!$L$2:$L$2000, Dati!$L$2:$L$2000, ">0")/ABS(SUMIFS(Dati!$L$2:$L$2000, Dati!$L$2:$L$2000, "<0")),0) -> 0
A15: DD Max | B15: =IFERROR(MIN(Dati!$T$2:$T$2000),0) -> 0.0175
A16: Colonna1 | B16: Numero Operazioni | C16: Risultato Medio % | D16: Profit Factor
A17: Long | B17: =COUNTIFS(Dati!$F$2:$F$2000,"Long",Dati!$L$2:$L$2000,"<>") -> 1 | C17: =IFERROR(AVERAGEIFS(Dati!$L$2:$L$2000, Dati!$F$2:$F$2000, "Long"),"") -> 0.0175 | D17: =IFERROR(SUMIFS(Dati!$L$2:$L$2000, Dati!$F$2:$F$2000, "Long", Dati!$L$2:$L$2000, ">0")/ABS(SUMIFS(Dati!$L$2:$L$2000, Dati!$F$2:$F$2000, "Long", Dati!$L$2:$L$2000, "<0")),0) -> 0
A18: Short | B18: =COUNTIFS(Dati!$F$2:$F$2000,"Short",Dati!$L$2:$L$2000,"<>") -> 0 | C18: =IFERROR(AVERAGEIFS(Dati!$L$2:$L$2000, Dati!$F$2:$F$2000, "Short"),"") | D18: =IFERROR(SUMIFS(Dati!$L$2:$L$2000, Dati!$F$2:$F$2000, "Short", Dati!$L$2:$L$2000, ">0")/ABS(SUMIFS(Dati!$L$2:$L$2000, Dati!$F$2:$F$2000, "Short", Dati!$L$2:$L$2000, "<0")),0) -> 0
A19: Breakeven | B19: =COUNTIFS(Dati!$K$2:$K$2000,"Breakeven",Dati!$L$2:$L$2000,"<>") -> 0 | C19: =IFERROR(AVERAGEIFS(Dati!$L$2:$L$2000, Dati!$K$2:$K$2000, "Breakeven"),"") | D19: =IFERROR(SUMIFS(Dati!$L$2:$L$2000, Dati!$K$2:$K$2000, "Breakeven", Dati!$L$2:$L$2000, ">0")/ABS(SUMIFS(Dati!$L$2:$L$2000, Dati!$K$2:$K$2000, "Breakeven", Dati!$L$2:$L$2000, "<0")),0) -> 0
A20: Conteggio di Risultato | B20: Etichette di colonna
A21: Etichette di riga | B21: Breakeven | C21: Stop Loss | D21: Target
A22: 06 | B22: 1 | C22: 1 | D22: 1
A23: 07 | D23: 1
A24: 08 | D24: 1
A25: 11 | C25: 2
A26: 16 | D26: 1
A27: 20 | C27: 1
A28: 23 | D28: 1
A29: Emozione | B29: Numero | C29: Risultato Medio %
A30: ansia | B30: =COUNTIF(Dati!$U$2:$U$2000, "ansia") -> 0 | C30: =IFERROR(AVERAGEIFS(Dati!$L$2:$L$2000, Dati!$U$2:$U$2000, "ansia"), "")
A31: calma | B31: =COUNTIF(Dati!$U$2:$U$2000, "calma") -> 0 | C31: =IFERROR(AVERAGEIFS(Dati!$L$2:$L$2000, Dati!$U$2:$U$2000, "calma"), "")
A32: fiducioso | B32: =COUNTIF(Dati!$U$2:$U$2000, "fiducioso") -> 0 | C32: =IFERROR(AVERAGEIFS(Dati!$L$2:$L$2000, Dati!$U$2:$U$2000, "fiducioso"), "")
A33: impaziente | B33: =COUNTIF(Dati!$U$2:$U$2000, "impaziente") -> 0 | C33: =IFERROR(AVERAGEIFS(Dati!$L$2:$L$2000, Dati!$U$2:$U$2000, "impaziente"), "")
A34: paura | B34: =COUNTIF(Dati!$U$2:$U$2000, "paura") -> 0 | C34: =IFERROR(AVERAGEIFS(Dati!$L$2:$L$2000, Dati!$U$2:$U$2000, "paura"), "")
A35: sicuro | B35: =COUNTIF(Dati!$U$2:$U$2000, "sicuro") -> 0 | C35: =IFERROR(AVERAGEIFS(Dati!$L$2:$L$2000, Dati!$U$2:$U$2000, "sicuro"), "")
A36: stress | B36: =COUNTIF(Dati!$U$2:$U$2000, "stress") -> 0 | C36: =IFERROR(AVERAGEIFS(Dati!$L$2:$L$2000, Dati!$U$2:$U$2000, "stress"), "")
A37: Conteggio di Risultato | B37: Etichette di colonna
A38: Etichette di riga | B38: Breakeven | C38: Stop Loss | D38: Target
A39: d1 | D39: 2
A40: h1 | D40: 2
...
